{"trial_id": "0", "hyperparameters": {"space": [{"class_name": "Choice", "config": {"name": "text_block_1/bert_block_1/max_sequence_length", "default": 128, "conditions": [], "values": [128, 256, 512], "ordered": true}}, {"class_name": "Choice", "config": {"name": "classification_head_1/dropout", "default": 0, "conditions": [], "values": [0.0, 0.25, 0.5], "ordered": true}}, {"class_name": "Choice", "config": {"name": "optimizer", "default": "adam", "conditions": [], "values": ["adam", "sgd", "adam_weight_decay"], "ordered": false}}, {"class_name": "Choice", "config": {"name": "learning_rate", "default": 0.001, "conditions": [], "values": [0.1, 0.01, 0.001, 0.0001, 2e-05, 1e-05], "ordered": true}}], "values": {"classification_head_1/dropout": 0, "optimizer": "adam_weight_decay", "learning_rate": 2e-05, "text_block_1/bert_block_1/max_sequence_length": 512}}, "metrics": {"metrics": {}}, "score": null, "best_step": 0, "status": "FAILED", "message": "Traceback (most recent call last):\n  File \"/home/cristian-msi/anaconda3/envs/prova/lib/python3.10/site-packages/keras_tuner/src/engine/base_tuner.py\", line 274, in _try_run_and_update_trial\n    self._run_and_update_trial(trial, *fit_args, **fit_kwargs)\n  File \"/home/cristian-msi/anaconda3/envs/prova/lib/python3.10/site-packages/keras_tuner/src/engine/base_tuner.py\", line 239, in _run_and_update_trial\n    results = self.run_trial(trial, *fit_args, **fit_kwargs)\n  File \"/home/cristian-msi/anaconda3/envs/prova/lib/python3.10/site-packages/keras_tuner/src/engine/tuner.py\", line 314, in run_trial\n    obj_value = self._build_and_fit_model(trial, *args, **copied_kwargs)\n  File \"/home/cristian-msi/anaconda3/envs/prova/lib/python3.10/site-packages/autokeras/engine/tuner.py\", line 102, in _build_and_fit_model\n    _, history = utils.fit_with_adaptive_batch_size(\n  File \"/home/cristian-msi/anaconda3/envs/prova/lib/python3.10/site-packages/autokeras/utils/utils.py\", line 69, in fit_with_adaptive_batch_size\n    history = run_with_adaptive_batch_size(\n  File \"/home/cristian-msi/anaconda3/envs/prova/lib/python3.10/site-packages/autokeras/utils/utils.py\", line 82, in run_with_adaptive_batch_size\n    history = func(x=x, validation_data=validation_data, **fit_kwargs)\n  File \"/home/cristian-msi/anaconda3/envs/prova/lib/python3.10/site-packages/autokeras/utils/utils.py\", line 70, in <lambda>\n    batch_size, lambda **kwargs: model.fit(**kwargs), **fit_kwargs\n  File \"/home/cristian-msi/anaconda3/envs/prova/lib/python3.10/site-packages/keras/src/utils/traceback_utils.py\", line 122, in error_handler\n    raise e.with_traceback(filtered_tb) from None\n  File \"/home/cristian-msi/anaconda3/envs/prova/lib/python3.10/site-packages/tensorflow/python/eager/execute.py\", line 53, in quick_execute\n    tensors = pywrap_tfe.TFE_Py_Execute(ctx._handle, device_name, op_name,\ntensorflow.python.framework.errors_impl.InvalidArgumentError: Graph execution error:\n\nDetected at node data defined at (most recent call last):\n<stack traces unavailable>\nDetected at node data defined at (most recent call last):\n<stack traces unavailable>\nDetected unsupported operations when trying to compile graph __inference_one_step_on_data_57504[] on XLA_GPU_JIT: _Arg (No registered '_Arg' OpKernel for XLA_GPU_JIT devices compatible with node {{node data}}\n\t (OpKernel was found, but attributes didn't match) Requested Attributes: T=DT_STRING, _output_shapes=[[2]], _user_specified_name=\"data\", index=0){{node data}}\nThe op is created at: \nFile \"Documents/AISE_Ch3/automl/autokeras_example.py\", line 43, in <module>\nFile \"anaconda3/envs/prova/lib/python3.10/site-packages/autokeras/tasks/text.py\", line 163, in fit\nFile \"anaconda3/envs/prova/lib/python3.10/site-packages/autokeras/auto_model.py\", line 303, in fit\nFile \"anaconda3/envs/prova/lib/python3.10/site-packages/autokeras/engine/tuner.py\", line 202, in search\nFile \"anaconda3/envs/prova/lib/python3.10/site-packages/keras_tuner/src/engine/base_tuner.py\", line 234, in search\nFile \"anaconda3/envs/prova/lib/python3.10/site-packages/keras_tuner/src/engine/base_tuner.py\", line 274, in _try_run_and_update_trial\nFile \"anaconda3/envs/prova/lib/python3.10/site-packages/keras_tuner/src/engine/base_tuner.py\", line 239, in _run_and_update_trial\nFile \"anaconda3/envs/prova/lib/python3.10/site-packages/keras_tuner/src/engine/tuner.py\", line 314, in run_trial\nFile \"anaconda3/envs/prova/lib/python3.10/site-packages/autokeras/engine/tuner.py\", line 102, in _build_and_fit_model\nFile \"anaconda3/envs/prova/lib/python3.10/site-packages/autokeras/utils/utils.py\", line 69, in fit_with_adaptive_batch_size\nFile \"anaconda3/envs/prova/lib/python3.10/site-packages/autokeras/utils/utils.py\", line 82, in run_with_adaptive_batch_size\nFile \"anaconda3/envs/prova/lib/python3.10/site-packages/autokeras/utils/utils.py\", line 70, in <lambda>\nFile \"anaconda3/envs/prova/lib/python3.10/site-packages/keras/src/utils/traceback_utils.py\", line 117, in error_handler\nFile \"anaconda3/envs/prova/lib/python3.10/site-packages/keras/src/backend/tensorflow/trainer.py\", line 320, in fit\nFile \"anaconda3/envs/prova/lib/python3.10/site-packages/keras/src/backend/tensorflow/trainer.py\", line 121, in one_step_on_iterator\nFile \"anaconda3/envs/prova/lib/python3.10/site-packages/tensorflow/core/function/polymorphism/function_type.py\", line 356, in placeholder_arguments\nFile \"anaconda3/envs/prova/lib/python3.10/site-packages/tensorflow/core/function/trace_type/default_types.py\", line 250, in placeholder_value\nFile \"anaconda3/envs/prova/lib/python3.10/site-packages/tensorflow/core/function/trace_type/default_types.py\", line 251, in <listcomp>\n\ttf2xla conversion failed while converting __inference_one_step_on_data_57504[]. Run with TF_DUMP_GRAPH_PREFIX=/path/to/dump/dir and --vmodule=xla_compiler=2 to obtain a dump of the compiled functions.\n\t [[StatefulPartitionedCall]] [Op:__inference_one_step_on_iterator_58801]\n"}